<?xml version="1.0"?>
<robot name="bipedal">

  <!-- core -->
  <link name="core">
   <visual>
     <geometry>
       <box size="0.7 1.3 0.2" />
     </geometry>
     <origin rpy="0 0 0" xyz="0 0 0.9"/>
   </visual>
   <collision>
     <geometry>
       <box size="0.7 1.3 0.2" />
     </geometry>
     <origin rpy="0 0 0" xyz="0 0 0.9"/>
   </collision>
   <inertial>
     <mass value="30"/>
     <inertia ixx="7.208" iyy="0.333" izz="7.208"/>
   </inertial>
  </link>


  <!-- front left leg -->

  <joint name="core_left_shoulder" type="revolute">
    <axis xyz="0 1 0"/>
    <limit effort="100" velocity="100" lower="-0.785398" upper="0.785398"/>
    <parent link="core"/>
    <child link="left_shoulder"/>
    <origin xyz="-0.33911 0.5175 0.9"/>
  </joint>

  <link name="left_shoulder">
    <visual>
      <geometry>
        <box size="0.2 0.2 0.2" />
      </geometry>
     <origin rpy="0 0 0" xyz="0 0 0"/>
    </visual>
    <inertial>
      <mass value="7"/>
      <inertia ixx="0.067" iyy="0.067" izz="0.067"/>
    </inertial>
  </link>

  <joint name="left_shoulder_left_leg_top" type="revolute">
    <axis xyz="1 0 0"/>
    <limit effort="100" velocity="100" lower="-0.785398" upper="0.785398"/>
    <parent link="left_shoulder"/>
    <child link="left_leg_top"/>
    <origin xyz="-0.24389 0 -0.04505"/>
  </joint>

  <link name="left_leg_top">
    <visual>
      <geometry>
        <box size="0.15 0.15 0.4" />
      </geometry>
     <origin rpy="0 0 0" xyz="0 0 -0.1"/>
    </visual>
    <inertial>
      <mass value="7"/>
      <inertia ixx="0.152" iyy="0.267" izz="0.152"/>
    </inertial>
  </link>

  <joint name="left_leg_top_left_leg_bottom" type="revolute">
    <axis xyz="1 0 0"/>
    <limit effort="100" velocity="100" lower="-0.785398" upper="0.785398"/>
    <parent link="left_leg_top"/>
    <child link="left_leg_bottom"/>
    <origin xyz="0 0 -0.45983"/>
  </joint>

  <link name="left_leg_bottom">
    <visual>
      <geometry>
        <box size="0.1 0.1 0.775" />
      </geometry>
     <origin rpy="0 0 0" xyz="0 0 -0.25"/>
    </visual>
    <collision>
      <contact_coefficient mu="10"  resitution="0"  k_p="0"  k_d="0" />
      <geometry>
        <box size="0.1 0.1 0.775" />
      </geometry>
      <origin rpy="0 0 0" xyz="0 0 -0.25"/>
    </collision>
    <inertial>
      <mass value="3"/>
      <inertia ixx="0.509" iyy="1.001" izz="0.509"/>
    </inertial>
  </link>



  <!-- front right leg -->

  <joint name="core_right_shoulder" type="revolute">
    <axis xyz="0 1 0"/>
    <limit effort="100" velocity="100" lower="-0.785398" upper="0.785398"/>
    <parent link="core"/>
    <child link="right_shoulder"/>
    <origin xyz="0.33911 0.5175 0.9"/>
  </joint>

  <link name="right_shoulder">
    <visual>
      <geometry>
        <box size="0.2 0.2 0.2" />
      </geometry>
     <origin rpy="0 0 0" xyz="0 0 0"/>
    </visual>
    <inertial>
      <mass value="7"/>
      <inertia ixx="0.067" iyy="0.067" izz="0.067"/>
    </inertial>
  </link>

  <joint name="right_shoulder_right_leg_top" type="revolute">
    <axis xyz="1 0 0"/>
    <limit effort="100" velocity="100" lower="-0.785398" upper="0.785398"/>
    <parent link="right_shoulder"/>
    <child link="right_leg_top"/>
    <origin xyz="0.24389 0 -0.04505"/>
  </joint>

  <link name="right_leg_top">
    <visual>
      <geometry>
        <box size="0.15 0.15 0.4" />
      </geometry>
     <origin rpy="0 0 0" xyz="0 0 -0.1"/>
    </visual>
    <inertial>
      <mass value="7"/>
      <inertia ixx="0.152" iyy="0.267" izz="0.152"/>
    </inertial>
  </link>

  <joint name="right_leg_top_right_leg_bottom" type="revolute">
    <axis xyz="1 0 0"/>
    <limit effort="100" velocity="100" lower="-0.785398" upper="0.785398"/>
    <parent link="right_leg_top"/>
    <child link="right_leg_bottom"/>
    <origin xyz="0 0 -0.45983"/>
  </joint>

  <link name="right_leg_bottom">
    <visual>
      <geometry>
        <box size="0.1 0.1 0.775" />
      </geometry>
     <origin rpy="0 0 0" xyz="0 0 -0.25"/>
    </visual>
    <collision>
      <contact_coefficient mu="10"  resitution="0"  k_p="0"  k_d="0" />
      <geometry>
        <box size="0.1 0.1 0.775" />
      </geometry>
      <origin rpy="0 0 0" xyz="0 0 -0.25"/>
    </collision>
    <inertial>
      <mass value="3"/>
      <inertia ixx="0.509" iyy="1.001" izz="0.509"/>
    </inertial>
  </link>



  <!-- back left leg -->

  <joint name="core_back_left_shoulder" type="revolute">
    <axis xyz="0 1 0"/>
    <limit effort="100" velocity="100" lower="-0.785398" upper="0.785398"/>
    <parent link="core"/>
    <child link="back_left_shoulder"/>
    <origin xyz="-0.33911 -0.5175 0.9"/>
  </joint>

  <link name="back_left_shoulder">
    <visual>
      <geometry>
        <box size="0.2 0.2 0.2" />
      </geometry>
     <origin rpy="0 0 0" xyz="0 0 0"/>
    </visual>
    <inertial>
      <mass value="7"/>
      <inertia ixx="0.067" iyy="0.067" izz="0.067"/>
    </inertial>
  </link>

  <joint name="back_left_shoulder_back_right_leg_top" type="revolute">
    <axis xyz="1 0 0"/>
    <limit effort="100" velocity="100" lower="-0.785398" upper="0.785398"/>
    <parent link="back_left_shoulder"/>
    <child link="back_left_leg_top"/>
    <origin xyz="-0.24389 0 -0.04505"/>
  </joint>

  <link name="back_left_leg_top">
    <visual>
      <geometry>
        <box size="0.15 0.15 0.4" />
      </geometry>
     <origin rpy="0 0 0" xyz="0 0 -0.1"/>
    </visual>
    <inertial>
      <mass value="7"/>
      <inertia ixx="0.152" iyy="0.267" izz="0.152"/>
    </inertial>
  </link>

  <joint name="back_left_leg_top_back_left_leg_bottom" type="revolute">
    <axis xyz="1 0 0"/>
    <limit effort="100" velocity="100" lower="-0.785398" upper="0.785398"/>
    <parent link="back_left_leg_top"/>
    <child link="back_left_leg_bottom"/>
    <origin xyz="0 0 -0.45983"/>
  </joint>

  <link name="back_left_leg_bottom">
    <visual>
      <geometry>
        <box size="0.1 0.1 0.775" />
      </geometry>
     <origin rpy="0 0 0" xyz="0 0 -0.25"/>
    </visual>
    <collision>
      <contact_coefficient mu="10"  resitution="0"  k_p="0"  k_d="0" />
      <geometry>
        <box size="0.1 0.1 0.775" />
      </geometry>
      <origin rpy="0 0 0" xyz="0 0 -0.25"/>
    </collision>
    <inertial>
      <mass value="3"/>
      <inertia ixx="0.509" iyy="1.001" izz="0.509"/>
    </inertial>
  </link>



  <!-- back right leg -->

  <joint name="core_back_right_shoulder" type="revolute">
    <axis xyz="0 1 0"/>
    <limit effort="100" velocity="100" lower="-0.785398" upper="0.785398"/>
    <parent link="core"/>
    <child link="back_right_shoulder"/>
    <origin xyz="0.33911 -0.5175 0.9"/>
  </joint>

  <link name="back_right_shoulder">
    <visual>
      <geometry>
        <box size="0.2 0.2 0.2" />
      </geometry>
     <origin rpy="0 0 0" xyz="0 0 0 "/>
    </visual>
    <inertial>
      <mass value="7"/>
      <inertia ixx="0.067" iyy="0.067" izz="0.067"/>
    </inertial>
  </link>

  <joint name="back_right_shoulder_back_right_leg_top" type="revolute">
    <axis xyz="1 0 0"/>
    <limit effort="100" velocity="100" lower="-0.785398" upper="0.785398"/>
    <parent link="back_right_shoulder"/>
    <child link="back_right_leg_top"/>
    <origin xyz="0.24389 0 -0.04505"/>
  </joint>

  <link name="back_right_leg_top">
    <visual>
      <geometry>
        <box size="0.15 0.15 0.4" />
      </geometry>
     <origin rpy="0 0 0" xyz="0 0 -0.1"/>
    </visual>
    <inertial>
      <mass value="7"/>
      <inertia ixx="0.152" iyy="0.267" izz="0.152"/>
    </inertial>
  </link>

  <joint name="back_right_leg_top_back_right_leg_bottom" type="revolute">
    <axis xyz="1 0 0"/>
    <limit effort="100" velocity="100" lower="-0.785398" upper="0.785398"/>
    <parent link="back_right_leg_top"/>
    <child link="back_right_leg_bottom"/>
    <origin xyz="0 0 -0.45983"/>
  </joint>

  <link name="back_right_leg_bottom">
    <visual>
      <geometry>
        <box size="0.1 0.1 0.775" />
      </geometry>
     <origin rpy="0 0 0" xyz="0 0 -0.25"/>
    </visual>
    <collision>
      <contact_coefficient mu="10"  resitution="0"  k_p="0"  k_d="0" />
      <geometry>
        <box size="0.1 0.1 0.775" />
      </geometry>
     <origin rpy="0 0 0" xyz="0 0 -0.25"/>
    </collision>
    <inertial>
      <mass value="3"/>
      <inertia ixx="0.509" iyy="1.001" izz="0.509"/>
    </inertial>
  </link>

</robot>
